[2023-10-22 13:07:29,189: INFO: main: >>>>>> stage Data Ingestion stage started <<<<<<]
[2023-10-22 13:07:29,196: INFO: common: yaml file: config\config.yaml loaded successfully]
[2023-10-22 13:07:29,201: INFO: common: yaml file: params.yaml loaded successfully]
[2023-10-22 13:07:29,202: INFO: common: created directory at: artifacts]
[2023-10-22 13:07:29,203: ERROR: main: 'ConfigurationManager' object has no attribute 'get_data_ingestion_config']
Traceback (most recent call last):
  File "main.py", line 10, in <module>
    data_ingestion.main()
  File "C:\Users\sumit\Desktop\Python_Dataset\Kidney-Disease-Classification-DVC-MLFlow\src\Stages\pipeline\Data_Ingestion_P.py", line 17, in main
    data_ingestion_config = config.get_data_ingestion_config()
AttributeError: 'ConfigurationManager' object has no attribute 'get_data_ingestion_config'
[2023-10-22 13:14:13,389: INFO: common: yaml file: config\config.yaml loaded successfully]
[2023-10-22 13:14:13,404: INFO: common: yaml file: params.yaml loaded successfully]
[2023-10-22 13:14:13,417: INFO: common: created directory at: artifacts]
[2023-10-22 13:14:13,424: INFO: common: created directory at: artifacts/data_ingestion]
[2023-10-22 13:14:13,434: INFO: 1168747554: Downloading data from https://drive.google.com/file/d/1TKxQZecX1YxOrxLt2y-XFhuxW733M81-/view?usp=sharing into file artifacts/data_ingestion/data.zip]
[2023-10-22 13:14:45,323: INFO: 1168747554: Downloaded data from https://drive.google.com/file/d/1TKxQZecX1YxOrxLt2y-XFhuxW733M81-/view?usp=sharing into file artifacts/data_ingestion/data.zip]
[2023-10-22 13:17:31,027: INFO: main: >>>>>> stage Data Ingestion stage started <<<<<<]
[2023-10-22 13:17:31,029: INFO: common: yaml file: config\config.yaml loaded successfully]
[2023-10-22 13:17:31,029: INFO: common: yaml file: params.yaml loaded successfully]
[2023-10-22 13:17:31,029: INFO: common: created directory at: artifacts]
[2023-10-22 13:17:31,039: INFO: common: created directory at: artifacts/data_ingestion]
[2023-10-22 13:17:31,040: INFO: Data_Ingestion: Downloading data from https://drive.google.com/file/d/1TKxQZecX1YxOrxLt2y-XFhuxW733M81-/view?usp=sharing into file artifacts/data_ingestion/data.zip]
[2023-10-22 13:17:46,565: INFO: Data_Ingestion: Downloaded data from https://drive.google.com/file/d/1TKxQZecX1YxOrxLt2y-XFhuxW733M81-/view?usp=sharing into file artifacts/data_ingestion/data.zip]
[2023-10-22 13:17:50,249: INFO: main: >>>>>> stage Data Ingestion stage completed <<<<<<

x==========x]
[2023-10-22 13:17:50,250: INFO: main: *******************]
[2023-10-22 13:17:50,252: INFO: main: >>>>>> stage Training started <<<<<<]
[2023-10-22 13:17:50,256: INFO: common: yaml file: config\config.yaml loaded successfully]
[2023-10-22 13:17:50,256: INFO: common: yaml file: params.yaml loaded successfully]
[2023-10-22 13:17:50,256: INFO: common: created directory at: artifacts]
[2023-10-22 13:17:50,274: ERROR: main: "'ConfigBox' object has no attribute 'prepare_base_model'"]
Traceback (most recent call last):
  File "box\box.py", line 503, in box.box.Box.__getitem__
KeyError: 'prepare_base_model'

The above exception was the direct cause of the following exception:

Traceback (most recent call last):
  File "box\box.py", line 536, in box.box.Box.__getattr__
  File "box\box.py", line 524, in box.box.Box.__getitem__
box.exceptions.BoxKeyError: "'prepare_base_model'"

During handling of the above exception, another exception occurred:

Traceback (most recent call last):
  File "box\box.py", line 538, in box.box.Box.__getattr__
AttributeError: 'ConfigBox' object has no attribute 'prepare_base_model'

The above exception was the direct cause of the following exception:

Traceback (most recent call last):
  File "box\config_box.py", line 28, in box.config_box.ConfigBox.__getattr__
  File "box\box.py", line 552, in box.box.Box.__getattr__
box.exceptions.BoxKeyError: "'ConfigBox' object has no attribute 'prepare_base_model'"

During handling of the above exception, another exception occurred:

Traceback (most recent call last):
  File "box\box.py", line 503, in box.box.Box.__getitem__
KeyError: 'prepare_base_model'

The above exception was the direct cause of the following exception:

Traceback (most recent call last):
  File "box\box.py", line 536, in box.box.Box.__getattr__
  File "box\box.py", line 524, in box.box.Box.__getitem__
box.exceptions.BoxKeyError: "'prepare_base_model'"

During handling of the above exception, another exception occurred:

Traceback (most recent call last):
  File "box\box.py", line 538, in box.box.Box.__getattr__
AttributeError: 'ConfigBox' object has no attribute 'prepare_base_model'

The above exception was the direct cause of the following exception:

Traceback (most recent call last):
  File "main.py", line 21, in <module>
    model_trainer.main()
  File "C:\Users\sumit\Desktop\Python_Dataset\Kidney-Disease-Classification-DVC-MLFlow\src\Stages\pipeline\Model_Train_P.py", line 18, in main
    training_config = config.get_training_config()
  File "C:\Users\sumit\Desktop\Python_Dataset\Kidney-Disease-Classification-DVC-MLFlow\src\Stages\config\configuration.py", line 33, in get_training_config
    prepare_base_model = self.config.prepare_base_model
  File "box\config_box.py", line 30, in box.config_box.ConfigBox.__getattr__
  File "box\box.py", line 552, in box.box.Box.__getattr__
box.exceptions.BoxKeyError: "'ConfigBox' object has no attribute 'prepare_base_model'"
[2023-10-22 13:23:56,076: INFO: main: *******************]
[2023-10-22 13:23:56,076: INFO: main: >>>>>> stage Training started <<<<<<]
[2023-10-22 13:23:56,079: INFO: common: yaml file: config\config.yaml loaded successfully]
[2023-10-22 13:23:56,079: INFO: common: yaml file: params.yaml loaded successfully]
[2023-10-22 13:23:56,079: INFO: common: created directory at: artifacts]
[2023-10-22 13:23:56,088: INFO: common: created directory at: artifacts\training]
[2023-10-22 13:25:42,808: INFO: main: >>>>>> stage Training completed <<<<<<

x==========x]
